2018-10-19 16:04:33,788 ERROR: Exception on /index [GET] [in D:\PycharmProjects\FlaskWeb\venv\lib\site-packages\flask\app.py:1761]
Traceback (most recent call last):
  File "D:\Anaconda3\lib\site-packages\sqlalchemy\engine\base.py", line 1193, in _execute_context
    context)
  File "D:\Anaconda3\lib\site-packages\sqlalchemy\engine\default.py", line 507, in do_execute
    cursor.execute(statement, parameters)
sqlite3.OperationalError: no such table: follows

The above exception was the direct cause of the following exception:

Traceback (most recent call last):
  File "D:\PycharmProjects\FlaskWeb\venv\lib\site-packages\flask\app.py", line 2292, in wsgi_app
    response = self.full_dispatch_request()
  File "D:\PycharmProjects\FlaskWeb\venv\lib\site-packages\flask\app.py", line 1815, in full_dispatch_request
    rv = self.handle_user_exception(e)
  File "D:\PycharmProjects\FlaskWeb\venv\lib\site-packages\flask\app.py", line 1718, in handle_user_exception
    reraise(exc_type, exc_value, tb)
  File "D:\PycharmProjects\FlaskWeb\venv\lib\site-packages\flask\_compat.py", line 35, in reraise
    raise value
  File "D:\PycharmProjects\FlaskWeb\venv\lib\site-packages\flask\app.py", line 1813, in full_dispatch_request
    rv = self.dispatch_request()
  File "D:\PycharmProjects\FlaskWeb\venv\lib\site-packages\flask\app.py", line 1799, in dispatch_request
    return self.view_functions[rule.endpoint](**req.view_args)
  File "D:\Anaconda3\lib\site-packages\flask_login\utils.py", line 261, in decorated_view
    return func(*args, **kwargs)
  File "D:\PycharmProjects\FlaskWeb\app\routes.py", line 41, in index
    posts = current_user.followed_posts().paginate(page, app.config['POSTS_PER_PAGE'], False)
  File "D:\Anaconda3\lib\site-packages\flask_sqlalchemy\__init__.py", line 491, in paginate
    items = self.limit(per_page).offset((page - 1) * per_page).all()
  File "D:\Anaconda3\lib\site-packages\sqlalchemy\orm\query.py", line 2737, in all
    return list(self)
  File "D:\Anaconda3\lib\site-packages\sqlalchemy\orm\query.py", line 2889, in __iter__
    return self._execute_and_instances(context)
  File "D:\Anaconda3\lib\site-packages\sqlalchemy\orm\query.py", line 2912, in _execute_and_instances
    result = conn.execute(querycontext.statement, self._params)
  File "D:\Anaconda3\lib\site-packages\sqlalchemy\engine\base.py", line 948, in execute
    return meth(self, multiparams, params)
  File "D:\Anaconda3\lib\site-packages\sqlalchemy\sql\elements.py", line 269, in _execute_on_connection
    return connection._execute_clauseelement(self, multiparams, params)
  File "D:\Anaconda3\lib\site-packages\sqlalchemy\engine\base.py", line 1060, in _execute_clauseelement
    compiled_sql, distilled_params
  File "D:\Anaconda3\lib\site-packages\sqlalchemy\engine\base.py", line 1200, in _execute_context
    context)
  File "D:\Anaconda3\lib\site-packages\sqlalchemy\engine\base.py", line 1413, in _handle_dbapi_exception
    exc_info
  File "D:\Anaconda3\lib\site-packages\sqlalchemy\util\compat.py", line 203, in raise_from_cause
    reraise(type(exception), exception, tb=exc_tb, cause=cause)
  File "D:\Anaconda3\lib\site-packages\sqlalchemy\util\compat.py", line 186, in reraise
    raise value.with_traceback(tb)
  File "D:\Anaconda3\lib\site-packages\sqlalchemy\engine\base.py", line 1193, in _execute_context
    context)
  File "D:\Anaconda3\lib\site-packages\sqlalchemy\engine\default.py", line 507, in do_execute
    cursor.execute(statement, parameters)
sqlalchemy.exc.OperationalError: (sqlite3.OperationalError) no such table: follows [SQL: 'SELECT anon_1.post_id AS anon_1_post_id, anon_1.post_body AS anon_1_post_body, anon_1.post_timestamp AS anon_1_post_timestamp, anon_1.post_user_id AS anon_1_post_user_id \nFROM (SELECT post.id AS post_id, post.body AS post_body, post.timestamp AS post_timestamp, post.user_id AS post_user_id \nFROM post JOIN follows ON follows.followed_id = post.user_id \nWHERE follows.follower_id = ? UNION SELECT post.id AS post_id, post.body AS post_body, post.timestamp AS post_timestamp, post.user_id AS post_user_id \nFROM post \nWHERE post.user_id = ?) AS anon_1 ORDER BY anon_1.post_timestamp DESC\n LIMIT ? OFFSET ?'] [parameters: (3, 3, 25, 0)] (Background on this error at: http://sqlalche.me/e/e3q8)
2018-10-19 16:05:00,942 INFO: Yuan_blog startup [in D:\PycharmProjects\FlaskWeb\app\__init__.py:58]
2018-10-19 16:05:10,066 INFO: Yuan_blog startup [in D:\PycharmProjects\FlaskWeb\app\__init__.py:58]
2018-10-19 16:07:33,759 INFO: Yuan_blog startup [in D:\PycharmProjects\FlaskWeb\app\__init__.py:58]
2018-10-19 16:11:25,049 INFO: Yuan_blog startup [in D:\PycharmProjects\FlaskWeb\app\__init__.py:58]
2018-10-19 16:18:29,921 INFO: Yuan_blog startup [in D:\PycharmProjects\FlaskWeb\app\__init__.py:58]
2018-10-19 16:20:05,417 INFO: Yuan_blog startup [in D:\PycharmProjects\FlaskWeb\app\__init__.py:58]
2018-10-19 16:21:09,712 INFO: Yuan_blog startup [in D:\PycharmProjects\FlaskWeb\app\__init__.py:58]
2018-10-19 16:23:09,844 INFO: Yuan_blog startup [in D:\PycharmProjects\FlaskWeb\app\__init__.py:58]
2018-10-19 16:23:38,621 INFO: Yuan_blog startup [in D:\PycharmProjects\FlaskWeb\app\__init__.py:58]
2018-10-19 16:24:23,868 INFO: Yuan_blog startup [in D:\PycharmProjects\FlaskWeb\app\__init__.py:58]
2018-10-19 16:57:33,751 INFO: Yuan_blog startup [in D:\PycharmProjects\FlaskWeb\app\__init__.py:58]
2018-10-19 17:17:43,729 INFO: Yuan_blog startup [in D:\PycharmProjects\FlaskWeb\app\__init__.py:58]
2018-10-19 17:21:58,125 INFO: Yuan_blog startup [in D:\PycharmProjects\FlaskWeb\app\__init__.py:58]
