2018-11-16 19:38:55,278 ERROR: Exception on /user/admin/popup [GET] [in D:\PycharmProjects\FlaskWeb\venv\lib\site-packages\flask\app.py:1761]
Traceback (most recent call last):
  File "D:\PycharmProjects\FlaskWeb\venv\lib\site-packages\flask\app.py", line 2292, in wsgi_app
    response = self.full_dispatch_request()
  File "D:\PycharmProjects\FlaskWeb\venv\lib\site-packages\flask\app.py", line 1815, in full_dispatch_request
    rv = self.handle_user_exception(e)
  File "D:\PycharmProjects\FlaskWeb\venv\lib\site-packages\flask\app.py", line 1718, in handle_user_exception
    reraise(exc_type, exc_value, tb)
  File "D:\PycharmProjects\FlaskWeb\venv\lib\site-packages\flask\_compat.py", line 35, in reraise
    raise value
  File "D:\PycharmProjects\FlaskWeb\venv\lib\site-packages\flask\app.py", line 1813, in full_dispatch_request
    rv = self.dispatch_request()
  File "D:\PycharmProjects\FlaskWeb\venv\lib\site-packages\flask\app.py", line 1799, in dispatch_request
    return self.view_functions[rule.endpoint](**req.view_args)
  File "D:\Anaconda3\lib\site-packages\flask_login\utils.py", line 261, in decorated_view
    return func(*args, **kwargs)
  File "D:\PycharmProjects\FlaskWeb\app\main\routes.py", line 200, in user_popup
    return render_template('user_popup.html', user=user)
  File "D:\PycharmProjects\FlaskWeb\venv\lib\site-packages\flask\templating.py", line 135, in render_template
    context, ctx.app)
  File "D:\PycharmProjects\FlaskWeb\venv\lib\site-packages\flask\templating.py", line 117, in _render
    rv = template.render(context)
  File "D:\PycharmProjects\FlaskWeb\venv\lib\site-packages\jinja2\asyncsupport.py", line 76, in render
    return original_render(self, *args, **kwargs)
  File "D:\PycharmProjects\FlaskWeb\venv\lib\site-packages\jinja2\environment.py", line 1008, in render
    return self.environment.handle_exception(exc_info, True)
  File "D:\PycharmProjects\FlaskWeb\venv\lib\site-packages\jinja2\environment.py", line 780, in handle_exception
    reraise(exc_type, exc_value, tb)
  File "D:\PycharmProjects\FlaskWeb\venv\lib\site-packages\jinja2\_compat.py", line 37, in reraise
    raise value.with_traceback(tb)
  File "D:\PycharmProjects\FlaskWeb\app\templates\user_popup.html", line 27, in top-level template code
    <a href="{{ url_for('main.unfollow', username=user.username) }}">
  File "D:\PycharmProjects\FlaskWeb\venv\lib\site-packages\flask\helpers.py", line 356, in url_for
    return appctx.app.handle_url_build_error(error, endpoint, values)
  File "D:\PycharmProjects\FlaskWeb\venv\lib\site-packages\flask\app.py", line 2061, in handle_url_build_error
    reraise(exc_type, exc_value, tb)
  File "D:\PycharmProjects\FlaskWeb\venv\lib\site-packages\flask\_compat.py", line 35, in reraise
    raise value
  File "D:\PycharmProjects\FlaskWeb\venv\lib\site-packages\flask\helpers.py", line 345, in url_for
    force_external=external)
  File "D:\PycharmProjects\FlaskWeb\venv\lib\site-packages\werkzeug\routing.py", line 1776, in build
    raise BuildError(endpoint, values, method, self)
werkzeug.routing.BuildError: Could not build url for endpoint 'main.unfollow' with values ['username']. Did you mean 'main.un_follow' instead?
2018-11-16 19:39:13,371 INFO: Yuan_blog startup [in D:\PycharmProjects\FlaskWeb\app\__init__.py:90]
2018-11-16 19:39:20,227 ERROR: Exception on /user/admin/popup [GET] [in D:\PycharmProjects\FlaskWeb\venv\lib\site-packages\flask\app.py:1761]
Traceback (most recent call last):
  File "D:\PycharmProjects\FlaskWeb\venv\lib\site-packages\flask\app.py", line 2292, in wsgi_app
    response = self.full_dispatch_request()
  File "D:\PycharmProjects\FlaskWeb\venv\lib\site-packages\flask\app.py", line 1815, in full_dispatch_request
    rv = self.handle_user_exception(e)
  File "D:\PycharmProjects\FlaskWeb\venv\lib\site-packages\flask\app.py", line 1718, in handle_user_exception
    reraise(exc_type, exc_value, tb)
  File "D:\PycharmProjects\FlaskWeb\venv\lib\site-packages\flask\_compat.py", line 35, in reraise
    raise value
  File "D:\PycharmProjects\FlaskWeb\venv\lib\site-packages\flask\app.py", line 1813, in full_dispatch_request
    rv = self.dispatch_request()
  File "D:\PycharmProjects\FlaskWeb\venv\lib\site-packages\flask\app.py", line 1799, in dispatch_request
    return self.view_functions[rule.endpoint](**req.view_args)
  File "D:\Anaconda3\lib\site-packages\flask_login\utils.py", line 261, in decorated_view
    return func(*args, **kwargs)
  File "D:\PycharmProjects\FlaskWeb\app\main\routes.py", line 200, in user_popup
    return render_template('user_popup.html', user=user)
  File "D:\PycharmProjects\FlaskWeb\venv\lib\site-packages\flask\templating.py", line 135, in render_template
    context, ctx.app)
  File "D:\PycharmProjects\FlaskWeb\venv\lib\site-packages\flask\templating.py", line 117, in _render
    rv = template.render(context)
  File "D:\PycharmProjects\FlaskWeb\venv\lib\site-packages\jinja2\asyncsupport.py", line 76, in render
    return original_render(self, *args, **kwargs)
  File "D:\PycharmProjects\FlaskWeb\venv\lib\site-packages\jinja2\environment.py", line 1008, in render
    return self.environment.handle_exception(exc_info, True)
  File "D:\PycharmProjects\FlaskWeb\venv\lib\site-packages\jinja2\environment.py", line 780, in handle_exception
    reraise(exc_type, exc_value, tb)
  File "D:\PycharmProjects\FlaskWeb\venv\lib\site-packages\jinja2\_compat.py", line 37, in reraise
    raise value.with_traceback(tb)
  File "D:\PycharmProjects\FlaskWeb\app\templates\user_popup.html", line 27, in top-level template code
    <a href="{{ url_for('main.unfollow', username=user.username) }}">
  File "D:\PycharmProjects\FlaskWeb\venv\lib\site-packages\flask\helpers.py", line 356, in url_for
    return appctx.app.handle_url_build_error(error, endpoint, values)
  File "D:\PycharmProjects\FlaskWeb\venv\lib\site-packages\flask\app.py", line 2061, in handle_url_build_error
    reraise(exc_type, exc_value, tb)
  File "D:\PycharmProjects\FlaskWeb\venv\lib\site-packages\flask\_compat.py", line 35, in reraise
    raise value
  File "D:\PycharmProjects\FlaskWeb\venv\lib\site-packages\flask\helpers.py", line 345, in url_for
    force_external=external)
  File "D:\PycharmProjects\FlaskWeb\venv\lib\site-packages\werkzeug\routing.py", line 1776, in build
    raise BuildError(endpoint, values, method, self)
werkzeug.routing.BuildError: Could not build url for endpoint 'main.unfollow' with values ['username']. Did you mean 'main.un_follow' instead?
2018-11-16 19:39:25,273 ERROR: Exception on /user/admin/popup [GET] [in D:\PycharmProjects\FlaskWeb\venv\lib\site-packages\flask\app.py:1761]
Traceback (most recent call last):
  File "D:\PycharmProjects\FlaskWeb\venv\lib\site-packages\flask\app.py", line 2292, in wsgi_app
    response = self.full_dispatch_request()
  File "D:\PycharmProjects\FlaskWeb\venv\lib\site-packages\flask\app.py", line 1815, in full_dispatch_request
    rv = self.handle_user_exception(e)
  File "D:\PycharmProjects\FlaskWeb\venv\lib\site-packages\flask\app.py", line 1718, in handle_user_exception
    reraise(exc_type, exc_value, tb)
  File "D:\PycharmProjects\FlaskWeb\venv\lib\site-packages\flask\_compat.py", line 35, in reraise
    raise value
  File "D:\PycharmProjects\FlaskWeb\venv\lib\site-packages\flask\app.py", line 1813, in full_dispatch_request
    rv = self.dispatch_request()
  File "D:\PycharmProjects\FlaskWeb\venv\lib\site-packages\flask\app.py", line 1799, in dispatch_request
    return self.view_functions[rule.endpoint](**req.view_args)
  File "D:\Anaconda3\lib\site-packages\flask_login\utils.py", line 261, in decorated_view
    return func(*args, **kwargs)
  File "D:\PycharmProjects\FlaskWeb\app\main\routes.py", line 200, in user_popup
    return render_template('user_popup.html', user=user)
  File "D:\PycharmProjects\FlaskWeb\venv\lib\site-packages\flask\templating.py", line 135, in render_template
    context, ctx.app)
  File "D:\PycharmProjects\FlaskWeb\venv\lib\site-packages\flask\templating.py", line 117, in _render
    rv = template.render(context)
  File "D:\PycharmProjects\FlaskWeb\venv\lib\site-packages\jinja2\asyncsupport.py", line 76, in render
    return original_render(self, *args, **kwargs)
  File "D:\PycharmProjects\FlaskWeb\venv\lib\site-packages\jinja2\environment.py", line 1008, in render
    return self.environment.handle_exception(exc_info, True)
  File "D:\PycharmProjects\FlaskWeb\venv\lib\site-packages\jinja2\environment.py", line 780, in handle_exception
    reraise(exc_type, exc_value, tb)
  File "D:\PycharmProjects\FlaskWeb\venv\lib\site-packages\jinja2\_compat.py", line 37, in reraise
    raise value.with_traceback(tb)
  File "D:\PycharmProjects\FlaskWeb\app\templates\user_popup.html", line 27, in top-level template code
    <a href="{{ url_for('main.unfollow', username=user.username) }}">
  File "D:\PycharmProjects\FlaskWeb\venv\lib\site-packages\flask\helpers.py", line 356, in url_for
    return appctx.app.handle_url_build_error(error, endpoint, values)
  File "D:\PycharmProjects\FlaskWeb\venv\lib\site-packages\flask\app.py", line 2061, in handle_url_build_error
    reraise(exc_type, exc_value, tb)
  File "D:\PycharmProjects\FlaskWeb\venv\lib\site-packages\flask\_compat.py", line 35, in reraise
    raise value
  File "D:\PycharmProjects\FlaskWeb\venv\lib\site-packages\flask\helpers.py", line 345, in url_for
    force_external=external)
  File "D:\PycharmProjects\FlaskWeb\venv\lib\site-packages\werkzeug\routing.py", line 1776, in build
    raise BuildError(endpoint, values, method, self)
werkzeug.routing.BuildError: Could not build url for endpoint 'main.unfollow' with values ['username']. Did you mean 'main.un_follow' instead?
