2018-11-15 21:03:08,530 ERROR: Exception on /api/users/1 [GET] [in D:\PycharmProjects\FlaskWeb\venv\lib\site-packages\flask\app.py:1761]
Traceback (most recent call last):
  File "D:\PycharmProjects\FlaskWeb\venv\lib\site-packages\flask\app.py", line 2292, in wsgi_app
    response = self.full_dispatch_request()
  File "D:\PycharmProjects\FlaskWeb\venv\lib\site-packages\flask\app.py", line 1815, in full_dispatch_request
    rv = self.handle_user_exception(e)
  File "D:\PycharmProjects\FlaskWeb\venv\lib\site-packages\flask\app.py", line 1718, in handle_user_exception
    reraise(exc_type, exc_value, tb)
  File "D:\PycharmProjects\FlaskWeb\venv\lib\site-packages\flask\_compat.py", line 35, in reraise
    raise value
  File "D:\PycharmProjects\FlaskWeb\venv\lib\site-packages\flask\app.py", line 1813, in full_dispatch_request
    rv = self.dispatch_request()
  File "D:\PycharmProjects\FlaskWeb\venv\lib\site-packages\flask\app.py", line 1799, in dispatch_request
    return self.view_functions[rule.endpoint](**req.view_args)
  File "D:\PycharmProjects\FlaskWeb\app\api\users.py", line 17, in get_user
    return jsonify(User.query.get_or_404(id).to_dict())
  File "D:\Anaconda3\lib\site-packages\flask_sqlalchemy\__init__.py", line 417, in get_or_404
    rv = self.get(ident)
  File "D:\Anaconda3\lib\site-packages\sqlalchemy\orm\query.py", line 864, in get
    return self._get_impl(ident, loading.load_on_ident)
  File "D:\Anaconda3\lib\site-packages\sqlalchemy\orm\query.py", line 897, in _get_impl
    return fallback_fn(self, key)
  File "D:\Anaconda3\lib\site-packages\sqlalchemy\orm\loading.py", line 223, in load_on_ident
    return q.one()
  File "D:\Anaconda3\lib\site-packages\sqlalchemy\orm\query.py", line 2814, in one
    ret = self.one_or_none()
  File "D:\Anaconda3\lib\site-packages\sqlalchemy\orm\query.py", line 2784, in one_or_none
    ret = list(self)
  File "D:\Anaconda3\lib\site-packages\sqlalchemy\orm\loading.py", line 90, in instances
    util.raise_from_cause(err)
  File "D:\Anaconda3\lib\site-packages\sqlalchemy\util\compat.py", line 203, in raise_from_cause
    reraise(type(exception), exception, tb=exc_tb, cause=cause)
  File "D:\Anaconda3\lib\site-packages\sqlalchemy\util\compat.py", line 187, in reraise
    raise value
  File "D:\Anaconda3\lib\site-packages\sqlalchemy\orm\loading.py", line 75, in instances
    rows = [proc(row) for row in fetch]
  File "D:\Anaconda3\lib\site-packages\sqlalchemy\orm\loading.py", line 75, in <listcomp>
    rows = [proc(row) for row in fetch]
  File "D:\Anaconda3\lib\site-packages\sqlalchemy\orm\loading.py", line 437, in _instance
    loaded_instance, populate_existing, populators)
  File "D:\Anaconda3\lib\site-packages\sqlalchemy\orm\loading.py", line 498, in _populate_full
    dict_[key] = getter(row)
ValueError: Couldn't parse datetime string '1540264690476' - value is not a string.
2018-11-15 21:14:06,286 ERROR: Exception on /api/users/3 [GET] [in D:\PycharmProjects\FlaskWeb\venv\lib\site-packages\flask\app.py:1761]
Traceback (most recent call last):
  File "D:\PycharmProjects\FlaskWeb\venv\lib\site-packages\flask\app.py", line 2292, in wsgi_app
    response = self.full_dispatch_request()
  File "D:\PycharmProjects\FlaskWeb\venv\lib\site-packages\flask\app.py", line 1815, in full_dispatch_request
    rv = self.handle_user_exception(e)
  File "D:\PycharmProjects\FlaskWeb\venv\lib\site-packages\flask\app.py", line 1718, in handle_user_exception
    reraise(exc_type, exc_value, tb)
  File "D:\PycharmProjects\FlaskWeb\venv\lib\site-packages\flask\_compat.py", line 35, in reraise
    raise value
  File "D:\PycharmProjects\FlaskWeb\venv\lib\site-packages\flask\app.py", line 1813, in full_dispatch_request
    rv = self.dispatch_request()
  File "D:\PycharmProjects\FlaskWeb\venv\lib\site-packages\flask\app.py", line 1799, in dispatch_request
    return self.view_functions[rule.endpoint](**req.view_args)
  File "D:\PycharmProjects\FlaskWeb\app\api\users.py", line 17, in get_user
    return jsonify(User.query.get_or_404(id).to_dict())
  File "D:\PycharmProjects\FlaskWeb\app\models.py", line 114, in to_dict
    'last_date': self.last_date.isoformat() + 'Z',
AttributeError: 'NoneType' object has no attribute 'isoformat'
2018-11-15 21:18:25,045 INFO: Yuan_blog startup [in D:\PycharmProjects\FlaskWeb\app\__init__.py:90]
