2018-10-29 18:14:20,289 ERROR: Exception on /explore [GET] [in D:\Anaconda3\lib\site-packages\flask\app.py:1560]
Traceback (most recent call last):
  File "D:\Anaconda3\lib\site-packages\flask\app.py", line 1982, in wsgi_app
    response = self.full_dispatch_request()
  File "D:\Anaconda3\lib\site-packages\flask\app.py", line 1614, in full_dispatch_request
    rv = self.handle_user_exception(e)
  File "D:\Anaconda3\lib\site-packages\flask\app.py", line 1517, in handle_user_exception
    reraise(exc_type, exc_value, tb)
  File "D:\Anaconda3\lib\site-packages\flask\_compat.py", line 33, in reraise
    raise value
  File "D:\Anaconda3\lib\site-packages\flask\app.py", line 1612, in full_dispatch_request
    rv = self.dispatch_request()
  File "D:\Anaconda3\lib\site-packages\flask\app.py", line 1598, in dispatch_request
    return self.view_functions[rule.endpoint](**req.view_args)
  File "D:\Anaconda3\lib\site-packages\flask_login\utils.py", line 261, in decorated_view
    return func(*args, **kwargs)
  File "D:\PycharmProjects\FlaskWeb\app\main\routes.py", line 156, in explore
    next_url=next_url, prev_url=prev_url)
  File "D:\Anaconda3\lib\site-packages\flask\templating.py", line 134, in render_template
    context, ctx.app)
  File "D:\Anaconda3\lib\site-packages\flask\templating.py", line 116, in _render
    rv = template.render(context)
  File "D:\Anaconda3\lib\site-packages\jinja2\asyncsupport.py", line 76, in render
    return original_render(self, *args, **kwargs)
  File "D:\Anaconda3\lib\site-packages\jinja2\environment.py", line 1008, in render
    return self.environment.handle_exception(exc_info, True)
  File "D:\Anaconda3\lib\site-packages\jinja2\environment.py", line 780, in handle_exception
    reraise(exc_type, exc_value, tb)
  File "D:\Anaconda3\lib\site-packages\jinja2\_compat.py", line 37, in reraise
    raise value.with_traceback(tb)
  File "D:\PycharmProjects\FlaskWeb\app\templates\index.html", line 2, in top-level template code
    {% import 'bootstrap/wtf.html' as wtf %}
  File "D:\PycharmProjects\FlaskWeb\app\templates\base.html", line 1, in top-level template code
    {% extends 'bootstrap/base.html' %}
  File "D:\Anaconda3\lib\site-packages\flask_bootstrap\templates\bootstrap\base.html", line 1, in top-level template code
    {% block doc -%}
  File "D:\Anaconda3\lib\site-packages\flask_bootstrap\templates\bootstrap\base.html", line 4, in block "doc"
    {%- block html %}
  File "D:\Anaconda3\lib\site-packages\flask_bootstrap\templates\bootstrap\base.html", line 20, in block "html"
    {% block body -%}
  File "D:\Anaconda3\lib\site-packages\flask_bootstrap\templates\bootstrap\base.html", line 21, in block "body"
    {% block navbar %}
  File "D:\PycharmProjects\FlaskWeb\app\templates\base.html", line 26, in block "navbar"
    <form class="navbar-form navbar-left" method="get" action="{{ url_for('main.search') }}">
  File "D:\Anaconda3\lib\site-packages\flask\helpers.py", line 333, in url_for
    return appctx.app.handle_url_build_error(error, endpoint, values)
  File "D:\Anaconda3\lib\site-packages\flask\app.py", line 1805, in handle_url_build_error
    reraise(exc_type, exc_value, tb)
  File "D:\Anaconda3\lib\site-packages\flask\_compat.py", line 33, in reraise
    raise value
  File "D:\Anaconda3\lib\site-packages\flask\helpers.py", line 323, in url_for
    force_external=external)
  File "D:\Anaconda3\lib\site-packages\werkzeug\routing.py", line 1768, in build
    raise BuildError(endpoint, values, method, self)
werkzeug.routing.BuildError: Could not build url for endpoint 'main.search'. Did you mean 'main.user' instead?
2018-10-29 18:20:51,278 INFO: Yuan_blog startup [in D:\PycharmProjects\FlaskWeb\app\__init__.py:88]
2018-10-29 18:21:14,017 ERROR: Exception on /explore [GET] [in D:\Anaconda3\lib\site-packages\flask\app.py:1560]
Traceback (most recent call last):
  File "D:\Anaconda3\lib\site-packages\flask\app.py", line 1982, in wsgi_app
    response = self.full_dispatch_request()
  File "D:\Anaconda3\lib\site-packages\flask\app.py", line 1614, in full_dispatch_request
    rv = self.handle_user_exception(e)
  File "D:\Anaconda3\lib\site-packages\flask\app.py", line 1517, in handle_user_exception
    reraise(exc_type, exc_value, tb)
  File "D:\Anaconda3\lib\site-packages\flask\_compat.py", line 33, in reraise
    raise value
  File "D:\Anaconda3\lib\site-packages\flask\app.py", line 1612, in full_dispatch_request
    rv = self.dispatch_request()
  File "D:\Anaconda3\lib\site-packages\flask\app.py", line 1598, in dispatch_request
    return self.view_functions[rule.endpoint](**req.view_args)
  File "D:\Anaconda3\lib\site-packages\flask_login\utils.py", line 261, in decorated_view
    return func(*args, **kwargs)
  File "D:\PycharmProjects\FlaskWeb\app\main\routes.py", line 156, in explore
    next_url=next_url, prev_url=prev_url)
  File "D:\Anaconda3\lib\site-packages\flask\templating.py", line 134, in render_template
    context, ctx.app)
  File "D:\Anaconda3\lib\site-packages\flask\templating.py", line 116, in _render
    rv = template.render(context)
  File "D:\Anaconda3\lib\site-packages\jinja2\asyncsupport.py", line 76, in render
    return original_render(self, *args, **kwargs)
  File "D:\Anaconda3\lib\site-packages\jinja2\environment.py", line 1008, in render
    return self.environment.handle_exception(exc_info, True)
  File "D:\Anaconda3\lib\site-packages\jinja2\environment.py", line 780, in handle_exception
    reraise(exc_type, exc_value, tb)
  File "D:\Anaconda3\lib\site-packages\jinja2\_compat.py", line 37, in reraise
    raise value.with_traceback(tb)
  File "D:\PycharmProjects\FlaskWeb\app\templates\index.html", line 2, in top-level template code
    {% import 'bootstrap/wtf.html' as wtf %}
  File "D:\PycharmProjects\FlaskWeb\app\templates\base.html", line 1, in top-level template code
    {% extends 'bootstrap/base.html' %}
  File "D:\Anaconda3\lib\site-packages\flask_bootstrap\templates\bootstrap\base.html", line 1, in top-level template code
    {% block doc -%}
  File "D:\Anaconda3\lib\site-packages\flask_bootstrap\templates\bootstrap\base.html", line 4, in block "doc"
    {%- block html %}
  File "D:\Anaconda3\lib\site-packages\flask_bootstrap\templates\bootstrap\base.html", line 20, in block "html"
    {% block body -%}
  File "D:\Anaconda3\lib\site-packages\flask_bootstrap\templates\bootstrap\base.html", line 21, in block "body"
    {% block navbar %}
  File "D:\PycharmProjects\FlaskWeb\app\templates\base.html", line 26, in block "navbar"
    <form class="navbar-form navbar-left" method="get" action="{{ url_for('main.search') }}">
  File "D:\Anaconda3\lib\site-packages\flask\helpers.py", line 333, in url_for
    return appctx.app.handle_url_build_error(error, endpoint, values)
  File "D:\Anaconda3\lib\site-packages\flask\app.py", line 1805, in handle_url_build_error
    reraise(exc_type, exc_value, tb)
  File "D:\Anaconda3\lib\site-packages\flask\_compat.py", line 33, in reraise
    raise value
  File "D:\Anaconda3\lib\site-packages\flask\helpers.py", line 323, in url_for
    force_external=external)
  File "D:\Anaconda3\lib\site-packages\werkzeug\routing.py", line 1768, in build
    raise BuildError(endpoint, values, method, self)
werkzeug.routing.BuildError: Could not build url for endpoint 'main.search'. Did you mean 'main.user' instead?
