2018-10-24 20:29:02,476 INFO: Yuan_blog startup [in D:\PycharmProjects\FlaskWeb\app\__init__.py:85]
2018-10-24 20:29:05,792 ERROR: Exception on /auth/login [GET] [in D:\Anaconda3\lib\site-packages\flask\app.py:1560]
Traceback (most recent call last):
  File "D:\Anaconda3\lib\site-packages\flask\app.py", line 1982, in wsgi_app
    response = self.full_dispatch_request()
  File "D:\Anaconda3\lib\site-packages\flask\app.py", line 1614, in full_dispatch_request
    rv = self.handle_user_exception(e)
  File "D:\Anaconda3\lib\site-packages\flask\app.py", line 1517, in handle_user_exception
    reraise(exc_type, exc_value, tb)
  File "D:\Anaconda3\lib\site-packages\flask\_compat.py", line 33, in reraise
    raise value
  File "D:\Anaconda3\lib\site-packages\flask\app.py", line 1612, in full_dispatch_request
    rv = self.dispatch_request()
  File "D:\Anaconda3\lib\site-packages\flask\app.py", line 1598, in dispatch_request
    return self.view_functions[rule.endpoint](**req.view_args)
  File "D:\PycharmProjects\FlaskWeb\app\auth\routes.py", line 35, in login
    return render_template('login.html', title='Sign In', form=form)
  File "D:\Anaconda3\lib\site-packages\flask\templating.py", line 133, in render_template
    return _render(ctx.app.jinja_env.get_or_select_template(template_name_or_list),
  File "D:\Anaconda3\lib\site-packages\jinja2\environment.py", line 869, in get_or_select_template
    return self.get_template(template_name_or_list, parent, globals)
  File "D:\Anaconda3\lib\site-packages\jinja2\environment.py", line 830, in get_template
    return self._load_template(name, self.make_globals(globals))
  File "D:\Anaconda3\lib\site-packages\jinja2\environment.py", line 804, in _load_template
    template = self.loader.load(self, name, globals)
  File "D:\Anaconda3\lib\site-packages\jinja2\loaders.py", line 113, in load
    source, filename, uptodate = self.get_source(environment, name)
  File "D:\Anaconda3\lib\site-packages\flask\templating.py", line 57, in get_source
    return self._get_source_fast(environment, template)
  File "D:\Anaconda3\lib\site-packages\flask\templating.py", line 85, in _get_source_fast
    raise TemplateNotFound(template)
jinja2.exceptions.TemplateNotFound: login.html
2018-10-24 20:43:19,267 INFO: Yuan_blog startup [in D:\PycharmProjects\FlaskWeb\app\__init__.py:85]
2018-10-24 20:43:28,378 ERROR: Exception on /auth/login [GET] [in D:\Anaconda3\lib\site-packages\flask\app.py:1560]
Traceback (most recent call last):
  File "D:\Anaconda3\lib\site-packages\flask\app.py", line 1982, in wsgi_app
    response = self.full_dispatch_request()
  File "D:\Anaconda3\lib\site-packages\flask\app.py", line 1614, in full_dispatch_request
    rv = self.handle_user_exception(e)
  File "D:\Anaconda3\lib\site-packages\flask\app.py", line 1517, in handle_user_exception
    reraise(exc_type, exc_value, tb)
  File "D:\Anaconda3\lib\site-packages\flask\_compat.py", line 33, in reraise
    raise value
  File "D:\Anaconda3\lib\site-packages\flask\app.py", line 1612, in full_dispatch_request
    rv = self.dispatch_request()
  File "D:\Anaconda3\lib\site-packages\flask\app.py", line 1598, in dispatch_request
    return self.view_functions[rule.endpoint](**req.view_args)
  File "D:\PycharmProjects\FlaskWeb\app\auth\routes.py", line 35, in login
    return render_template('login.html', title='Sign In', form=form)
  File "D:\Anaconda3\lib\site-packages\flask\templating.py", line 133, in render_template
    return _render(ctx.app.jinja_env.get_or_select_template(template_name_or_list),
  File "D:\Anaconda3\lib\site-packages\jinja2\environment.py", line 869, in get_or_select_template
    return self.get_template(template_name_or_list, parent, globals)
  File "D:\Anaconda3\lib\site-packages\jinja2\environment.py", line 830, in get_template
    return self._load_template(name, self.make_globals(globals))
  File "D:\Anaconda3\lib\site-packages\jinja2\environment.py", line 804, in _load_template
    template = self.loader.load(self, name, globals)
  File "D:\Anaconda3\lib\site-packages\jinja2\loaders.py", line 113, in load
    source, filename, uptodate = self.get_source(environment, name)
  File "D:\Anaconda3\lib\site-packages\flask\templating.py", line 57, in get_source
    return self._get_source_fast(environment, template)
  File "D:\Anaconda3\lib\site-packages\flask\templating.py", line 85, in _get_source_fast
    raise TemplateNotFound(template)
jinja2.exceptions.TemplateNotFound: login.html
2018-10-24 21:02:21,121 INFO: Yuan_blog startup [in D:\PycharmProjects\FlaskWeb\app\__init__.py:85]
2018-10-24 21:02:52,539 ERROR: Exception on / [GET] [in D:\Anaconda3\lib\site-packages\flask\app.py:1560]
Traceback (most recent call last):
  File "D:\Anaconda3\lib\site-packages\flask\app.py", line 1982, in wsgi_app
    response = self.full_dispatch_request()
  File "D:\Anaconda3\lib\site-packages\flask\app.py", line 1614, in full_dispatch_request
    rv = self.handle_user_exception(e)
  File "D:\Anaconda3\lib\site-packages\flask\app.py", line 1517, in handle_user_exception
    reraise(exc_type, exc_value, tb)
  File "D:\Anaconda3\lib\site-packages\flask\_compat.py", line 33, in reraise
    raise value
  File "D:\Anaconda3\lib\site-packages\flask\app.py", line 1612, in full_dispatch_request
    rv = self.dispatch_request()
  File "D:\Anaconda3\lib\site-packages\flask\app.py", line 1598, in dispatch_request
    return self.view_functions[rule.endpoint](**req.view_args)
  File "D:\Anaconda3\lib\site-packages\flask_login\utils.py", line 261, in decorated_view
    return func(*args, **kwargs)
  File "D:\PycharmProjects\FlaskWeb\app\main\routes.py", line 51, in index
    posts = current_user.followed_posts().paginate(page, current_user.config['POSTS_PER_PAGE'], False)
  File "D:\Anaconda3\lib\site-packages\werkzeug\local.py", line 347, in __getattr__
    return getattr(self._get_current_object(), name)
AttributeError: 'User' object has no attribute 'config'
2018-10-24 21:02:58,449 ERROR: Exception on /index [GET] [in D:\Anaconda3\lib\site-packages\flask\app.py:1560]
Traceback (most recent call last):
  File "D:\Anaconda3\lib\site-packages\flask\app.py", line 1982, in wsgi_app
    response = self.full_dispatch_request()
  File "D:\Anaconda3\lib\site-packages\flask\app.py", line 1614, in full_dispatch_request
    rv = self.handle_user_exception(e)
  File "D:\Anaconda3\lib\site-packages\flask\app.py", line 1517, in handle_user_exception
    reraise(exc_type, exc_value, tb)
  File "D:\Anaconda3\lib\site-packages\flask\_compat.py", line 33, in reraise
    raise value
  File "D:\Anaconda3\lib\site-packages\flask\app.py", line 1612, in full_dispatch_request
    rv = self.dispatch_request()
  File "D:\Anaconda3\lib\site-packages\flask\app.py", line 1598, in dispatch_request
    return self.view_functions[rule.endpoint](**req.view_args)
  File "D:\Anaconda3\lib\site-packages\flask_login\utils.py", line 261, in decorated_view
    return func(*args, **kwargs)
  File "D:\PycharmProjects\FlaskWeb\app\main\routes.py", line 51, in index
    posts = current_user.followed_posts().paginate(page, current_user.config['POSTS_PER_PAGE'], False)
  File "D:\Anaconda3\lib\site-packages\werkzeug\local.py", line 347, in __getattr__
    return getattr(self._get_current_object(), name)
AttributeError: 'User' object has no attribute 'config'
2018-10-24 21:05:09,939 ERROR: Exception on /index [GET] [in D:\Anaconda3\lib\site-packages\flask\app.py:1560]
Traceback (most recent call last):
  File "D:\Anaconda3\lib\site-packages\flask\app.py", line 1982, in wsgi_app
    response = self.full_dispatch_request()
  File "D:\Anaconda3\lib\site-packages\flask\app.py", line 1614, in full_dispatch_request
    rv = self.handle_user_exception(e)
  File "D:\Anaconda3\lib\site-packages\flask\app.py", line 1517, in handle_user_exception
    reraise(exc_type, exc_value, tb)
  File "D:\Anaconda3\lib\site-packages\flask\_compat.py", line 33, in reraise
    raise value
  File "D:\Anaconda3\lib\site-packages\flask\app.py", line 1612, in full_dispatch_request
    rv = self.dispatch_request()
  File "D:\Anaconda3\lib\site-packages\flask\app.py", line 1598, in dispatch_request
    return self.view_functions[rule.endpoint](**req.view_args)
  File "D:\Anaconda3\lib\site-packages\flask_login\utils.py", line 261, in decorated_view
    return func(*args, **kwargs)
  File "D:\PycharmProjects\FlaskWeb\app\main\routes.py", line 51, in index
    posts = current_user.followed_posts().paginate(page, current_user.config['POSTS_PER_PAGE'], False)
  File "D:\Anaconda3\lib\site-packages\werkzeug\local.py", line 347, in __getattr__
    return getattr(self._get_current_object(), name)
AttributeError: 'User' object has no attribute 'config'
2018-10-24 21:05:11,289 ERROR: Exception on /index [GET] [in D:\Anaconda3\lib\site-packages\flask\app.py:1560]
Traceback (most recent call last):
  File "D:\Anaconda3\lib\site-packages\flask\app.py", line 1982, in wsgi_app
    response = self.full_dispatch_request()
  File "D:\Anaconda3\lib\site-packages\flask\app.py", line 1614, in full_dispatch_request
    rv = self.handle_user_exception(e)
  File "D:\Anaconda3\lib\site-packages\flask\app.py", line 1517, in handle_user_exception
    reraise(exc_type, exc_value, tb)
  File "D:\Anaconda3\lib\site-packages\flask\_compat.py", line 33, in reraise
    raise value
  File "D:\Anaconda3\lib\site-packages\flask\app.py", line 1612, in full_dispatch_request
    rv = self.dispatch_request()
  File "D:\Anaconda3\lib\site-packages\flask\app.py", line 1598, in dispatch_request
    return self.view_functions[rule.endpoint](**req.view_args)
  File "D:\Anaconda3\lib\site-packages\flask_login\utils.py", line 261, in decorated_view
    return func(*args, **kwargs)
  File "D:\PycharmProjects\FlaskWeb\app\main\routes.py", line 51, in index
    posts = current_user.followed_posts().paginate(page, current_user.config['POSTS_PER_PAGE'], False)
  File "D:\Anaconda3\lib\site-packages\werkzeug\local.py", line 347, in __getattr__
    return getattr(self._get_current_object(), name)
AttributeError: 'User' object has no attribute 'config'
