2018-10-19 10:49:09,042 ERROR: Exception on / [GET] [in D:\PycharmProjects\FlaskWeb\venv\lib\site-packages\flask\app.py:1761]
Traceback (most recent call last):
  File "D:\PycharmProjects\FlaskWeb\venv\lib\site-packages\flask\app.py", line 2292, in wsgi_app
    response = self.full_dispatch_request()
  File "D:\PycharmProjects\FlaskWeb\venv\lib\site-packages\flask\app.py", line 1815, in full_dispatch_request
    rv = self.handle_user_exception(e)
  File "D:\PycharmProjects\FlaskWeb\venv\lib\site-packages\flask\app.py", line 1718, in handle_user_exception
    reraise(exc_type, exc_value, tb)
  File "D:\PycharmProjects\FlaskWeb\venv\lib\site-packages\flask\_compat.py", line 35, in reraise
    raise value
  File "D:\PycharmProjects\FlaskWeb\venv\lib\site-packages\flask\app.py", line 1813, in full_dispatch_request
    rv = self.dispatch_request()
  File "D:\PycharmProjects\FlaskWeb\venv\lib\site-packages\flask\app.py", line 1799, in dispatch_request
    return self.view_functions[rule.endpoint](**req.view_args)
  File "D:\Anaconda3\lib\site-packages\flask_login\utils.py", line 261, in decorated_view
    return func(*args, **kwargs)
  File "D:\PycharmProjects\FlaskWeb\app\routes.py", line 49, in index
    prev_url=prev_url)
  File "D:\PycharmProjects\FlaskWeb\venv\lib\site-packages\flask\templating.py", line 135, in render_template
    context, ctx.app)
  File "D:\PycharmProjects\FlaskWeb\venv\lib\site-packages\flask\templating.py", line 117, in _render
    rv = template.render(context)
  File "D:\Anaconda3\lib\site-packages\jinja2\asyncsupport.py", line 76, in render
    return original_render(self, *args, **kwargs)
  File "D:\Anaconda3\lib\site-packages\jinja2\environment.py", line 1008, in render
    return self.environment.handle_exception(exc_info, True)
  File "D:\Anaconda3\lib\site-packages\jinja2\environment.py", line 780, in handle_exception
    reraise(exc_type, exc_value, tb)
  File "D:\Anaconda3\lib\site-packages\jinja2\_compat.py", line 37, in reraise
    raise value.with_traceback(tb)
  File "D:\PycharmProjects\FlaskWeb\app\templates\base.html", line 23, in template
    {% message %}
  File "D:\Anaconda3\lib\site-packages\jinja2\environment.py", line 1005, in render
    return concat(self.root_render_func(self.new_context(vars)))
  File "D:\PycharmProjects\FlaskWeb\app\templates\index.html", line 1, in top-level template code
    {% extends "base.html" %}
  File "D:\Anaconda3\lib\site-packages\jinja2\environment.py", line 780, in handle_exception
    reraise(exc_type, exc_value, tb)
  File "D:\Anaconda3\lib\site-packages\jinja2\_compat.py", line 37, in reraise
    raise value.with_traceback(tb)
  File "D:\PycharmProjects\FlaskWeb\app\templates\base.html", line 23, in template
    {% message %}
  File "D:\Anaconda3\lib\site-packages\jinja2\environment.py", line 497, in _parse
    return Parser(self, source, name, encode_filename(filename)).parse()
  File "D:\Anaconda3\lib\site-packages\jinja2\parser.py", line 901, in parse
    result = nodes.Template(self.subparse(), lineno=1)
  File "D:\Anaconda3\lib\site-packages\jinja2\parser.py", line 883, in subparse
    rv = self.parse_statement()
  File "D:\Anaconda3\lib\site-packages\jinja2\parser.py", line 130, in parse_statement
    return getattr(self, 'parse_' + self.stream.current.value)()
  File "D:\Anaconda3\lib\site-packages\jinja2\parser.py", line 268, in parse_block
    node.body = self.parse_statements(('name:endblock',), drop_needle=True)
  File "D:\Anaconda3\lib\site-packages\jinja2\parser.py", line 165, in parse_statements
    result = self.subparse(end_tokens)
  File "D:\Anaconda3\lib\site-packages\jinja2\parser.py", line 883, in subparse
    rv = self.parse_statement()
  File "D:\Anaconda3\lib\site-packages\jinja2\parser.py", line 130, in parse_statement
    return getattr(self, 'parse_' + self.stream.current.value)()
  File "D:\Anaconda3\lib\site-packages\jinja2\parser.py", line 243, in parse_with
    drop_needle=True)
  File "D:\Anaconda3\lib\site-packages\jinja2\parser.py", line 165, in parse_statements
    result = self.subparse(end_tokens)
  File "D:\Anaconda3\lib\site-packages\jinja2\parser.py", line 883, in subparse
    rv = self.parse_statement()
  File "D:\Anaconda3\lib\site-packages\jinja2\parser.py", line 130, in parse_statement
    return getattr(self, 'parse_' + self.stream.current.value)()
  File "D:\Anaconda3\lib\site-packages\jinja2\parser.py", line 213, in parse_if
    'name:endif'))
  File "D:\Anaconda3\lib\site-packages\jinja2\parser.py", line 165, in parse_statements
    result = self.subparse(end_tokens)
  File "D:\Anaconda3\lib\site-packages\jinja2\parser.py", line 883, in subparse
    rv = self.parse_statement()
  File "D:\Anaconda3\lib\site-packages\jinja2\parser.py", line 130, in parse_statement
    return getattr(self, 'parse_' + self.stream.current.value)()
  File "D:\Anaconda3\lib\site-packages\jinja2\parser.py", line 199, in parse_for
    body = self.parse_statements(('name:endfor', 'name:else'))
  File "D:\Anaconda3\lib\site-packages\jinja2\parser.py", line 165, in parse_statements
    result = self.subparse(end_tokens)
  File "D:\Anaconda3\lib\site-packages\jinja2\parser.py", line 883, in subparse
    rv = self.parse_statement()
  File "D:\Anaconda3\lib\site-packages\jinja2\parser.py", line 144, in parse_statement
    self.fail_unknown_tag(token.value, token.lineno)
  File "D:\Anaconda3\lib\site-packages\jinja2\parser.py", line 97, in fail_unknown_tag
    return self._fail_ut_eof(name, self._end_token_stack, lineno)
  File "D:\Anaconda3\lib\site-packages\jinja2\parser.py", line 90, in _fail_ut_eof
    self.fail(' '.join(message), lineno)
  File "D:\Anaconda3\lib\site-packages\jinja2\parser.py", line 59, in fail
    raise exc(msg, lineno, self.name, self.filename)
jinja2.exceptions.TemplateSyntaxError: Encountered unknown tag 'message'. Jinja was looking for the following tags: 'endfor' or 'else'. The innermost block that needs to be closed is 'for'.
2018-10-19 11:05:48,643 INFO: Yuan_blog startup [in D:\PycharmProjects\FlaskWeb\app\__init__.py:58]
2018-10-19 11:29:45,665 INFO: Yuan_blog startup [in D:\PycharmProjects\FlaskWeb\app\__init__.py:58]
2018-10-19 11:45:04,203 INFO: Yuan_blog startup [in D:\PycharmProjects\FlaskWeb\app\__init__.py:58]
2018-10-19 11:53:21,246 INFO: Yuan_blog startup [in D:\PycharmProjects\FlaskWeb\app\__init__.py:58]
2018-10-19 11:59:03,482 INFO: Yuan_blog startup [in D:\PycharmProjects\FlaskWeb\app\__init__.py:58]
2018-10-19 12:06:25,192 INFO: Yuan_blog startup [in D:\PycharmProjects\FlaskWeb\app\__init__.py:58]
2018-10-19 12:19:42,269 INFO: Yuan_blog startup [in D:\PycharmProjects\FlaskWeb\app\__init__.py:58]
2018-10-19 12:25:26,322 INFO: Yuan_blog startup [in D:\PycharmProjects\FlaskWeb\app\__init__.py:58]
2018-10-19 12:25:44,923 ERROR: Exception on /edit_profile [POST] [in D:\PycharmProjects\FlaskWeb\venv\lib\site-packages\flask\app.py:1761]
Traceback (most recent call last):
  File "D:\PycharmProjects\FlaskWeb\venv\lib\site-packages\flask\app.py", line 2292, in wsgi_app
    response = self.full_dispatch_request()
  File "D:\PycharmProjects\FlaskWeb\venv\lib\site-packages\flask\app.py", line 1815, in full_dispatch_request
    rv = self.handle_user_exception(e)
  File "D:\PycharmProjects\FlaskWeb\venv\lib\site-packages\flask\app.py", line 1718, in handle_user_exception
    reraise(exc_type, exc_value, tb)
  File "D:\PycharmProjects\FlaskWeb\venv\lib\site-packages\flask\_compat.py", line 35, in reraise
    raise value
  File "D:\PycharmProjects\FlaskWeb\venv\lib\site-packages\flask\app.py", line 1813, in full_dispatch_request
    rv = self.dispatch_request()
  File "D:\PycharmProjects\FlaskWeb\venv\lib\site-packages\flask\app.py", line 1799, in dispatch_request
    return self.view_functions[rule.endpoint](**req.view_args)
  File "D:\Anaconda3\lib\site-packages\flask_login\utils.py", line 261, in decorated_view
    return func(*args, **kwargs)
  File "D:\PycharmProjects\FlaskWeb\app\routes.py", line 131, in edit_profile
    return redirect(url_for('user'))
  File "D:\PycharmProjects\FlaskWeb\venv\lib\site-packages\flask\helpers.py", line 356, in url_for
    return appctx.app.handle_url_build_error(error, endpoint, values)
  File "D:\PycharmProjects\FlaskWeb\venv\lib\site-packages\flask\app.py", line 2061, in handle_url_build_error
    reraise(exc_type, exc_value, tb)
  File "D:\PycharmProjects\FlaskWeb\venv\lib\site-packages\flask\_compat.py", line 35, in reraise
    raise value
  File "D:\PycharmProjects\FlaskWeb\venv\lib\site-packages\flask\helpers.py", line 345, in url_for
    force_external=external)
  File "D:\Anaconda3\lib\site-packages\werkzeug\routing.py", line 1776, in build
    raise BuildError(endpoint, values, method, self)
werkzeug.routing.BuildError: Could not build url for endpoint 'user'. Did you forget to specify values ['username']?
